nbdev-hello-world
================

<!-- WARNING: THIS FILE WAS AUTOGENERATED! DO NOT EDIT! -->

## Install

``` sh
pip install nbdev_hello_world
```

## How to use

This file contains all the testcases of Functions written in
testing.ipynb .

## TestCases

``` python
class TestName(unittest.TestCase):
    def test_add(self):
        self.assertEqual(add(1,3),4)
        
    def test_subtract(self):
        self.assertEqual(subtract(1,3),-2)
        
    def test_multiply(self):
        self.assertEqual(multiply(1,3),3)
        
    def test_divide(self):
        self.assertEqual(divide(1,3),0.33)
```

    test_add (__main__.TestName) ... ok
    test_divide (__main__.TestName) ... ok
    test_multiply (__main__.TestName) ... ok
    test_subtract (__main__.TestName) ... ok

    ----------------------------------------------------------------------
    Ran 4 tests in 0.010s

    OK

### Testing using Fastcore

``` python
class TestName(unittest.TestCase):
    def test_add(self):
        assert add(1,3)== 4
        
    def test_subtract(self):
        assert subtract(1,3)== 4
        
    def test_multiply(self):
        test_eq(multiply(1,3), 3)
        
    def test_divide(self):
        test_eq(divide(1,3), 0.33)
```

    test_add (__main__.TestName) ... ok
    test_divide (__main__.TestName) ... ok
    test_multiply (__main__.TestName) ... ok
    test_subtract (__main__.TestName) ... FAIL

    ======================================================================
    FAIL: test_subtract (__main__.TestName)
    ----------------------------------------------------------------------
    Traceback (most recent call last):
      File "C:\Users\5115\AppData\Local\Temp\ipykernel_20628\4123861692.py", line 7, in test_subtract
        assert subtract(1,3)== 4
    AssertionError: assert -2 == 4
     +  where -2 = subtract(1, 3)

    ----------------------------------------------------------------------
    Ran 4 tests in 0.009s

    FAILED (failures=1)

### Other tests from Fastcore

``` python
class TestName(unittest.TestCase):
    
    def test_fail_pass(self):
        test_fail(divide(1,0))
        
    def test_fail_fail(self):
        test_fail(divide(1,3))
        
    def test_equality_pass(self):
        test(add(1,3),add(2,2), operator.eq)
        
    def test_equality_fail(self):
        test(add(1,3),add(3,2), operator.eq)
        
    def test_fail_lambda_fail(self):
        test_fail(lambda: test(add(1,3),add(2,2), operator.eq))
        
    def test_dtype_pass(self):
        test_eq_type(1,1) 
        
    def test_dtype_fail(self):
        test_eq_type(1,1.0)
        
    def test_same_pass(self):
        test_is(subtract(1,3),subtract(3,5))
        
    def test_same_fail(self):
        test_is(subtract(1,3),subtract(3,7))
        
    def test_equality_fail(self):
        test(add(1,3),add(3,2), operator.eq)
```

    test_dtype_fail (__main__.TestName) ... FAIL
    test_dtype_pass (__main__.TestName) ... ok
    test_equality_fail (__main__.TestName) ... FAIL
    test_equality_pass (__main__.TestName) ... ok
    test_fail_fail (__main__.TestName) ... ok
    test_fail_lambda_fail (__main__.TestName) ... FAIL
    test_fail_pass (__main__.TestName) ... ERROR
    test_same_fail (__main__.TestName) ... FAIL
    test_same_pass (__main__.TestName) ... ok

    ======================================================================
    ERROR: test_fail_pass (__main__.TestName)
    ----------------------------------------------------------------------
    Traceback (most recent call last):
      File "C:\Users\5115\AppData\Local\Temp\ipykernel_20628\52876440.py", line 5, in test_fail_pass
        test_fail(divide(1,0))
      File "c:\pankaj\nbdev\nbdev-hello-world\nbdev_hello_world\Functions.py", line 22, in divide
        raise ValueError("Cannot divide by 0")
    ValueError: Cannot divide by 0

    ======================================================================
    FAIL: test_dtype_fail (__main__.TestName)
    ----------------------------------------------------------------------
    Traceback (most recent call last):
      File "C:\Users\5115\AppData\Local\Temp\ipykernel_20628\52876440.py", line 23, in test_dtype_fail
        test_eq_type(1,1.0)
      File "C:\Users\5115\AppData\Local\miniconda3\envs\test_env\lib\site-packages\fastcore\test.py", line 43, in test_eq_type
        test_eq(type(a),type(b))
      File "C:\Users\5115\AppData\Local\miniconda3\envs\test_env\lib\site-packages\fastcore\test.py", line 37, in test_eq
        test(a,b,equals, cname='==')
      File "C:\Users\5115\AppData\Local\miniconda3\envs\test_env\lib\site-packages\fastcore\test.py", line 27, in test
        assert cmp(a,b),f"{cname}:\n{a}\n{b}"
    AssertionError: ==:
    <class 'int'>
    <class 'float'>

    ======================================================================
    FAIL: test_equality_fail (__main__.TestName)
    ----------------------------------------------------------------------
    Traceback (most recent call last):
      File "C:\Users\5115\AppData\Local\Temp\ipykernel_20628\52876440.py", line 32, in test_equality_fail
        test(add(1,3),add(3,2), operator.eq)
      File "C:\Users\5115\AppData\Local\miniconda3\envs\test_env\lib\site-packages\fastcore\test.py", line 27, in test
        assert cmp(a,b),f"{cname}:\n{a}\n{b}"
    AssertionError: eq:
    4
    5

    ======================================================================
    FAIL: test_fail_lambda_fail (__main__.TestName)
    ----------------------------------------------------------------------
    Traceback (most recent call last):
      File "C:\Users\5115\AppData\Local\Temp\ipykernel_20628\52876440.py", line 17, in test_fail_lambda_fail
        test_fail(lambda: test(add(1,3),add(2,2), operator.eq))
      File "C:\Users\5115\AppData\Local\miniconda3\envs\test_env\lib\site-packages\fastcore\test.py", line 21, in test_fail
        assert False,f"Expected exception but none raised. {msg}"
    AssertionError: Expected exception but none raised. 

    ======================================================================
    FAIL: test_same_fail (__main__.TestName)
    ----------------------------------------------------------------------
    Traceback (most recent call last):
      File "C:\Users\5115\AppData\Local\Temp\ipykernel_20628\52876440.py", line 29, in test_same_fail
        test_is(subtract(1,3),subtract(3,7))
      File "C:\Users\5115\AppData\Local\miniconda3\envs\test_env\lib\site-packages\fastcore\test.py", line 68, in test_is
        test(a,b,operator.is_, 'is')
      File "C:\Users\5115\AppData\Local\miniconda3\envs\test_env\lib\site-packages\fastcore\test.py", line 27, in test
        assert cmp(a,b),f"{cname}:\n{a}\n{b}"
    AssertionError: is:
    -2
    -4

    ----------------------------------------------------------------------
    Ran 9 tests in 0.033s

    FAILED (failures=4, errors=1)

### Testing using pytest

``` python
def test_add():
    assert add(1,3) == 4
    
def test_subtract():
    assert subtract(1,3) == 2
    
def test_multiply():
    assert multiply(1,3) == 3
    
def test_divide():
    assert divide(1,3) == 0.33
```

    .F..                                                                                         [100%]
    ============================================ FAILURES =============================================
    __________________________________________ test_subtract __________________________________________

        def test_subtract():
    >       assert subtract(1,3) == 2
    E       assert -2 == 2
    E        +  where -2 = subtract(1, 3)

    C:\Users\5115\AppData\Local\Temp\ipykernel_20628\2678314103.py:5: AssertionError
    ===================================== short test summary info =====================================
    FAILED t_bbf4078566044d6a9fd3395a9439b56e.py::test_subtract - assert -2 == 2
    1 failed, 3 passed in 0.04s
